Workbook

Sheet UPI_ NATIONAL_MONTHLY
A1: Month | B1: Year | C1: Volume (In Mn.) | D1: Value (In Cr.)
A2: April | B2: 2016 | C2: 0 | D2: 0 | G2: SUMMARY TABLE
A3: May | B3: 2016 | C3: 0 | D3: 0 | G3: Sum of Volume (In Mn.) | H3: Column Labels | T3: Sum of Value (In Cr.) | U3: Column Labels
A4: June | B4: 2016 | C4: 0 | D4: 0 | G4: Row Labels | H4: 2016 | I4: 2017 | J4: 2018 | K4: 2019 | L4: 2020 | M4: 2021 | N4: 2022 | O4: 2023 | P4: 2024 | Q4: 2025 | R4: Grand Total | T4: Row Labels | U4: 2016 | V4: 2017 | W4: 2018 | X4: 2019 | Y4: 2020 | Z4: 2021 | AA4: 2022 | AB4: 2023 | AC4: 2024 | AD4: 2025 | AE4: Grand Total
A5: July | B5: 2016 | C5: 0.09 | D5: 0.38 | G5: January | I5: 4.46 | J5: 151.83 | K5: 672.75 | L5: 1305.02 | M5: 2302.73 | N5: 4617.15 | O5: 8036.89 | P5: 12203.02 | Q5: 16996 | R5: 46289.85 | T5: January | V5: 1696.22 | W5: 15571.2 | X5: 109932.43 | Y5: 216242.97 | Z5: 431181.89 | AA5: 831993.11 | AB5: 1298726.6 | AC5: 1841084 | AD5: 2348037.1 | AE5: 7094465.5
A6: August | B6: 2016 | C6: 0.09 | D6: 3.09 | G6: February | I6: 4.38 | J6: 171.4 | K6: 674.19 | L6: 1325.69 | M6: 2292.9 | N6: 4527.49 | O6: 7534.76 | P6: 12102.67 | Q6: 16106.19 | R6: 44739.67 | T6: February | V6: 1937.71 | W6: 19126.2 | X6: 106737.12 | Y6: 222516.95 | Z6: 425062.76 | AA6: 826843 | AB6: 1235846.6 | AC6: 1827869.4 | AD6: 2196481.7 | AE6: 6862421.4
A7: September | B7: 2016 | C7: 0.09 | D7: 32.64 | G7: March | I7: 6.37 | J7: 178.05 | K7: 799.54 | L7: 1246.84 | M7: 2731.68 | N7: 5405.65 | O7: 8685.3 | P7: 13440 | Q7: 18301.51 | R7: 50794.94 | T7: March | V7: 2425.14 | W7: 24172.6 | X7: 133460.72 | Y7: 206462.31 | Z7: 504886.44 | AA7: 960581.66 | AB7: 1410443 | AC7: 1978353.2 | AD7: 2477221.6 | AE7: 7698006.7
A8: October | B8: 2016 | C8: 0.1 | D8: 48.57 | G8: April | H8: 0 | I8: 7.2 | J8: 190.08 | K8: 781.79 | L8: 999.57 | M8: 2641.06 | N8: 5583.05 | O8: 8863.26 | P8: 13303.99 | Q8: 17893.42 | R8: 50263.42 | T8: April | U8: 0 | V8: 2271.24 | W8: 27021.85 | X8: 142034.39 | Y8: 151140.66 | Z8: 493663.68 | AA8: 983302.27 | AB8: 1415504.7 | AC8: 1964464.5 | AD8: 2394925.9 | AE8: 7574329.2
A9: November | B9: 2016 | C9: 0.29 | D9: 100.46 | G9: May | H9: 0 | I9: 9.36 | J9: 189.48 | K9: 733.54 | L9: 1234.5 | M9: 2539.57 | N9: 5955.2 | O9: 9415.19 | P9: 14035.84 | Q9: 18677.46 | R9: 52790.14 | T9: May | U9: 0 | V9: 2797.07 | W9: 33288.51 | X9: 152449.29 | Y9: 218391.6 | Z9: 490638.65 | AA9: 1041520.1 | AB9: 1489145.4 | AC9: 2044937.1 | AD9: 2514297 | AE9: 7987464.7
A10: December | B10: 2016 | C10: 1.99 | D10: 707.93 | G10: June | H10: 0 | I10: 10.35 | J10: 246.37 | K10: 754.54 | L10: 1336.93 | M10: 2807.51 | N10: 5862.75 | O10: 9335.06 | P10: 13885.14 | Q10: 18395.01 | R10: 52633.66 | T10: June | U10: 0 | V10: 3098.36 | W10: 40834.03 | X10: 146566.35 | Y10: 261835 | Z10: 547373.17 | AA10: 1014384.3 | AB10: 1475464.3 | AC10: 2007081.2 | AD10: 2403930.7 | AE10: 7900567.4
A11: January | B11: 2017 | C11: 4.46 | D11: 1696.22 | G11: July | H11: 0.09 | I11: 11.63 | J11: 273.75 | K11: 822.29 | L11: 1497.36 | M11: 3247.82 | N11: 6288.4 | O11: 9964.61 | P11: 14435.55 | Q11: 19467.95 | R11: 56009.45 | T11: July | U11: 0.38 | V11: 3411.35 | W11: 51843.14 | X11: 146386.64 | Y11: 290537.86 | Z11: 606281.14 | AA11: 1062991.8 | AB11: 1533536.4 | AC11: 2064292.4 | AD11: 2508498.1 | AE11: 8267779.2
A12: February | B12: 2017 | C12: 4.38 | D12: 1937.71 | G12: August | H12: 0.09 | I12: 16.8 | J12: 312.02 | K12: 918.35 | L12: 1618.83 | M12: 3555.55 | N12: 6579.63 | O12: 10586.02 | P12: 14963.05 | Q12: 20008.31 | R12: 58558.65 | T12: August | U12: 3.09 | V12: 4156.62 | W12: 54212.26 | X12: 154504.89 | Y12: 298307.61 | Z12: 639116.95 | AA12: 1072792.7 | AB12: 1576536.6 | AC12: 2060735.6 | AD12: 2485472.9 | AE12: 8345839.1
A13: March | B13: 2017 | C13: 6.37 | D13: 2425.14 | G13: September | H13: 0.09 | I13: 30.98 | J13: 405.87 | K13: 955.02 | L13: 1800.14 | M13: 3654.3 | N13: 6780.8 | O13: 10555.69 | P13: 15041.75 | Q13: 19633.43 | R13: 58858.07 | T13: September | U13: 32.64 | V13: 5325.81 | W13: 59835.36 | X13: 161456.56 | Y13: 329027.66 | Z13: 654351.81 | AA13: 1116438.1 | AB13: 1579133.2 | AC13: 2063994.7 | AD13: 2489736.5 | AE13: 8459332.4
A14: April | B14: 2017 | C14: 7.2 | D14: 2271.24 | G14: October | H14: 0.1 | I14: 76.96 | J14: 482.36 | K14: 1148.36 | L14: 2071.62 | M14: 4218.65 | N14: 7305.42 | O14: 11408.79 | P14: 16584.97 | Q14: 20700.92 | R14: 63998.15 | T14: October | U14: 48.57 | V14: 7057.78 | W14: 74978.27 | X14: 191359.94 | Y14: 386106.74 | Z14: 771444.98 | AA14: 1211582.5 | AB14: 1715768.3 | AC14: 2349821.5 | AD14: 2727790.7 | AE14: 9435959.3
A15: May | B15: 2017 | C15: 9.36 | D15: 2797.07 | G15: November | H15: 0.29 | I15: 105.02 | J15: 524.94 | K15: 1218.77 | L15: 2210.23 | M15: 4186.48 | N15: 7309.45 | O15: 11235.29 | P15: 15482.02 | R15: 42272.49 | T15: November | U15: 100.46 | V15: 9669.33 | W15: 82232.21 | X15: 189229.09 | Y15: 390999.15 | Z15: 768436.11 | AA15: 1190593.4 | AB15: 1739740.6 | AC15: 2155187.4 | AE15: 6526187.8
A16: June | B16: 2017 | C16: 10.35 | D16: 3098.36 | G16: December | H16: 1.99 | I16: 145.64 | J16: 620.17 | K16: 1308.4 | L16: 2234.16 | M16: 4566.3 | N16: 7829.49 | O16: 12020.23 | P16: 16730.01 | R16: 45456.39 | T16: December | U16: 707.93 | V16: 13174.24 | W16: 102594.82 | X16: 202520.76 | Y16: 416176.21 | Z16: 826848.22 | AA16: 1282055 | AB16: 1822949.4 | AC16: 2324699.9 | AE16: 6991726.5
A17: July | B17: 2017 | C17: 11.63 | D17: 3411.35 | G17: Grand Total | H17: 2.65 | I17: 429.15 | J17: 3746.32 | K17: 10787.54 | L17: 18880.89 | M17: 38744.55 | N17: 74044.48 | O17: 117641.09 | P17: 172208.01 | Q17: 186180.2 | R17: 622664.88 | T17: Grand Total | U17: 893.07 | V17: 57020.87 | W17: 585710.45 | X17: 1836638.2 | Y17: 3387744.7 | Z17: 7159285.8 | AA17: 12595078 | AB17: 18292795 | AC17: 24682521 | AD17: 24546392 | AE17: 93144079
A18: August | B18: 2017 | C18: 16.8 | D18: 4156.62
A19: September | B19: 2017 | C19: 30.98 | D19: 5325.81
A20: October | B20: 2017 | C20: 76.96 | D20: 7057.78
A21: November | B21: 2017 | C21: 105.02 | D21: 9669.33
A22: December | B22: 2017 | C22: 145.64 | D22: 13174.24
A23: January | B23: 2018 | C23: 151.83 | D23: 15571.2
A24: February | B24: 2018 | C24: 171.4 | D24: 19126.2
A25: March | B25: 2018 | C25: 178.05 | D25: 24172.6
A26: April | B26: 2018 | C26: 190.08 | D26: 27021.85 | G26: Row Labels | H26: 2016 | I26: 2017 | J26: 2018 | K26: 2019 | L26: 2020 | M26: 2021 | N26: 2022 | O26: 2023 | P26: 2024 | Q26: 2025 | T26: Row Labels | U26: 2016 | V26: 2017 | W26: 2018 | X26: 2019 | Y26: 2020 | Z26: 2021 | AA26: 2022 | AB26: 2023 | AC26: 2024 | AD26: 2025
A27: May | B27: 2018 | C27: 189.48 | D27: 33288.51 | G27: January | I27: 4.46 | J27: 151.83 | K27: 672.75 | L27: 1305.02 | M27: 2302.73 | N27: 4617.15 | O27: 8036.89 | P27: 12203.02 | Q27: 16996 | T27: January | V27: 1696.22 | W27: 15571.2 | X27: 109932.43 | Y27: 216242.97 | Z27: 431181.89 | AA27: 831993.11 | AB27: 1298726.6 | AC27: 1841084 | AD27: 2348037.1
A28: June | B28: 2018 | C28: 246.37 | D28: 40834.03 | G28: February | I28: 4.38 | J28: 171.4 | K28: 674.19 | L28: 1325.69 | M28: 2292.9 | N28: 4527.49 | O28: 7534.76 | P28: 12102.67 | Q28: 16106.19 | T28: February | V28: 1937.71 | W28: 19126.2 | X28: 106737.12 | Y28: 222516.95 | Z28: 425062.76 | AA28: 826843 | AB28: 1235846.6 | AC28: 1827869.4 | AD28: 2196481.7
A29: July | B29: 2018 | C29: 273.75 | D29: 51843.14 | G29: March | I29: 6.37 | J29: 178.05 | K29: 799.54 | L29: 1246.84 | M29: 2731.68 | N29: 5405.65 | O29: 8685.3 | P29: 13440 | Q29: 18301.51 | T29: March | V29: 2425.14 | W29: 24172.6 | X29: 133460.72 | Y29: 206462.31 | Z29: 504886.44 | AA29: 960581.66 | AB29: 1410443 | AC29: 1978353.2 | AD29: 2477221.6
A30: August | B30: 2018 | C30: 312.02 | D30: 54212.26 | G30: April | H30: 0 | I30: 7.2 | J30: 190.08 | K30: 781.79 | L30: 999.57 | M30: 2641.06 | N30: 5583.05 | O30: 8863.26 | P30: 13303.99 | Q30: 17893.42 | T30: April | U30: 0 | V30: 2271.24 | W30: 27021.85 | X30: 142034.39 | Y30: 151140.66 | Z30: 493663.68 | AA30: 983302.27 | AB30: 1415504.7 | AC30: 1964464.5 | AD30: 2394925.9
A31: September | B31: 2018 | C31: 405.87 | D31: 59835.36 | G31: May | H31: 0 | I31: 9.36 | J31: 189.48 | K31: 733.54 | L31: 1234.5 | M31: 2539.57 | N31: 5955.2 | O31: 9415.19 | P31: 14035.84 | Q31: 18677.46 | T31: May | U31: 0 | V31: 2797.07 | W31: 33288.51 | X31: 152449.29 | Y31: 218391.6 | Z31: 490638.65 | AA31: 1041520.1 | AB31: 1489145.4 | AC31: 2044937.1 | AD31: 2514297
A32: October | B32: 2018 | C32: 482.36 | D32: 74978.27 | G32: June | H32: 0 | I32: 10.35 | J32: 246.37 | K32: 754.54 | L32: 1336.93 | M32: 2807.51 | N32: 5862.75 | O32: 9335.06 | P32: 13885.14 | Q32: 18395.01 | T32: June | U32: 0 | V32: 3098.36 | W32: 40834.03 | X32: 146566.35 | Y32: 261835 | Z32: 547373.17 | AA32: 1014384.3 | AB32: 1475464.3 | AC32: 2007081.2 | AD32: 2403930.7
A33: November | B33: 2018 | C33: 524.94 | D33: 82232.21 | G33: July | H33: 0.09 | I33: 11.63 | J33: 273.75 | K33: 822.29 | L33: 1497.36 | M33: 3247.82 | N33: 6288.4 | O33: 9964.61 | P33: 14435.55 | Q33: 19467.95 | T33: July | U33: 0.38 | V33: 3411.35 | W33: 51843.14 | X33: 146386.64 | Y33: 290537.86 | Z33: 606281.14 | AA33: 1062991.8 | AB33: 1533536.4 | AC33: 2064292.4 | AD33: 2508498.1
A34: December | B34: 2018 | C34: 620.17 | D34: 102594.82 | G34: August | H34: 0.09 | I34: 16.8 | J34: 312.02 | K34: 918.35 | L34: 1618.83 | M34: 3555.55 | N34: 6579.63 | O34: 10586.02 | P34: 14963.05 | Q34: 20008.31 | T34: August | U34: 3.09 | V34: 4156.62 | W34: 54212.26 | X34: 154504.89 | Y34: 298307.61 | Z34: 639116.95 | AA34: 1072792.7 | AB34: 1576536.6 | AC34: 2060735.6 | AD34: 2485472.9
A35: January | B35: 2019 | C35: 672.75 | D35: 109932.43 | G35: September | H35: 0.09 | I35: 30.98 | J35: 405.87 | K35: 955.02 | L35: 1800.14 | M35: 3654.3 | N35: 6780.8 | O35: 10555.69 | P35: 15041.75 | Q35: 19633.43 | T35: September | U35: 32.64 | V35: 5325.81 | W35: 59835.36 | X35: 161456.56 | Y35: 329027.66 | Z35: 654351.81 | AA35: 1116438.1 | AB35: 1579133.2 | AC35: 2063994.7 | AD35: 2489736.5
A36: February | B36: 2019 | C36: 674.19 | D36: 106737.12 | G36: October | H36: 0.1 | I36: 76.96 | J36: 482.36 | K36: 1148.36 | L36: 2071.62 | M36: 4218.65 | N36: 7305.42 | O36: 11408.79 | P36: 16584.97 | Q36: 20700.92 | T36: October | U36: 48.57 | V36: 7057.78 | W36: 74978.27 | X36: 191359.94 | Y36: 386106.74 | Z36: 771444.98 | AA36: 1211582.5 | AB36: 1715768.3 | AC36: 2349821.5 | AD36: 2727790.7
A37: March | B37: 2019 | C37: 799.54 | D37: 133460.72 | G37: November | H37: 0.29 | I37: 105.02 | J37: 524.94 | K37: 1218.77 | L37: 2210.23 | M37: 4186.48 | N37: 7309.45 | O37: 11235.29 | P37: 15482.02 | T37: November | U37: 100.46 | V37: 9669.33 | W37: 82232.21 | X37: 189229.09 | Y37: 390999.15 | Z37: 768436.11 | AA37: 1190593.4 | AB37: 1739740.6 | AC37: 2155187.4
A38: April | B38: 2019 | C38: 781.79 | D38: 142034.39 | G38: December | H38: 1.99 | I38: 145.64 | J38: 620.17 | K38: 1308.4 | L38: 2234.16 | M38: 4566.3 | N38: 7829.49 | O38: 12020.23 | P38: 16730.01 | T38: December | U38: 707.93 | V38: 13174.24 | W38: 102594.82 | X38: 202520.76 | Y38: 416176.21 | Z38: 826848.22 | AA38: 1282055 | AB38: 1822949.4 | AC38: 2324699.9
A39: May | B39: 2019 | C39: 733.54 | D39: 152449.29
A40: June | B40: 2019 | C40: 754.54 | D40: 146566.35
...

Sheet UPI_National_Fin_Annual
A1: Financial YEAR | B1: ANNUAL TRANSACTIONS (in Mn.) | C1: ANNUAL VALUE (Rs. in Cr.)
A2: 2016-17 | B2: =SUM('UPI_ NATIONAL_MONTHLY'!C2:C13) -> 17.86 | C2: =SUM('UPI_ NATIONAL_MONTHLY'!D2:D13) -> 6952.14
A3: 2017-18 | B3: =SUM('UPI_ NATIONAL_MONTHLY'!C14:C25) -> 915.22 | C3: =SUM('UPI_ NATIONAL_MONTHLY'!D14:D25) -> 109831.8
A4: 2018-19 | B4: =SUM('UPI_ NATIONAL_MONTHLY'!C26:C37) -> 5391.52 | C4: =SUM('UPI_ NATIONAL_MONTHLY'!D26:D37) -> 876970.72
A5: 2019-20 | B5: =SUM('UPI_ NATIONAL_MONTHLY'!C38:C49) -> 12518.61 | C5: =SUM('UPI_ NATIONAL_MONTHLY'!D38:D49) -> 2131730.1
A6: 2020-21 | B6: =SUM('UPI_ NATIONAL_MONTHLY'!C50:C61) -> 22330.65 | C6: =SUM('UPI_ NATIONAL_MONTHLY'!D50:D61) -> 4103653.6
A7: 2021-22 | B7: =SUM('UPI_ NATIONAL_MONTHLY'!C62:C73) -> 45967.53 | C7: =SUM('UPI_ NATIONAL_MONTHLY'!D62:D73) -> 8417572.5
A8: 2022-23 | B8: =SUM('UPI_ NATIONAL_MONTHLY'!C74:C85) -> 83751.14 | C8: =SUM('UPI_ NATIONAL_MONTHLY'!D74:D85) -> 13920676
A9: 2023-24 | B9: =SUM('UPI_ NATIONAL_MONTHLY'!C86:C97) -> 131129.83 | C9: =SUM('UPI_ NATIONAL_MONTHLY'!D86:D97) -> 19995086
A10: 2024-25 | B10: =SUM('UPI_ NATIONAL_MONTHLY'!C98:C109) -> 185866.02 | C10: =SUM('UPI_ NATIONAL_MONTHLY'!D98:D109) -> 26056955
A12: ABSOLUTE INCREASE | B12: =B10-B2 -> 185848.16 | C12: =C10-C2 -> 26050003
A13: MULTIPLE | B13: =B10/B2 -> 10406.832 | C13: =C10/C2 -> 3748.048
A14: CAGR (Compund Annual Growth Rate) % | B14: =(B13^(1/9)-1)*100 -> 179.49158 | C14: =(C13^(1/9)-1)*100 -> 149.51086 | H14: NOTE: 2025 November and December data is not included
A16: CAGR = [(Ending Value / Beginning Value)^(1 / Number of Years)] – 1

Sheet REATIL GSVA WORK
F3: NOTES: SINCE SOME STATES DON'T HAVE GSVA DATA OF 2024-25 THESE CALCULATIONS EXCLUDE 2024-25 DATA OF ALL STATES
C4: Retail_GSVA (Rs. in lakh) | D4: Column Labels
C5: States | D5: 2011-12 | E5: 2023-24 | F5: Grand Total (All Years) | G5: Absolute Increase | H5: Growth % | I5: Growth Category | J5: Size Category
C7: Maharashtra | D7: 10560912 | E7: 17628321 | F7: 1.9894967e+08 | G7: =E7-D7 -> 7067408.3 | H7: =((E7-D7)/D7)*100 -> 66.920433 | I7: =IF(H7>=_xlfn.PERCENTILE.INC($H$7:$H$39,0.75),"High",IF(H7<=_xlfn.PERCENTILE.INC($H$7:$H$39,0.25),"Low","Medium")) -> Low | J7: =IF(E7>=_xlfn.PERCENTILE.INC($E$7:$E$39,0.75),"High Size", IF(E7<=_xlfn.PERCENTILE.INC($E$7:$E$39,0.25),"Low Size","Medium Size")) -> High Size
C8: Gujarat | D8: 6646396.1 | E8: 17034179 | F8: 1.5072178e+08 | G8: =E8-D8 -> 10387783 | H8: =((E8-D8)/D8)*100 -> 156.29196 | I8: =IF(H8>=_xlfn.PERCENTILE.INC($H$7:$H$39,0.75),"High",IF(H8<=_xlfn.PERCENTILE.INC($H$7:$H$39,0.25),"Low","Medium")) -> High | J8: =IF(E8>=_xlfn.PERCENTILE.INC($E$7:$E$39,0.75),"High Size", IF(E8<=_xlfn.PERCENTILE.INC($E$7:$E$39,0.25),"Low Size","Medium Size")) -> High Size
C9: Tamil Nadu | D9: 7930218.9 | E9: 15904886 | F9: 1.7057555e+08 | G9: =E9-D9 -> 7974667 | H9: =((E9-D9)/D9)*100 -> 100.56049 | I9: =IF(H9>=_xlfn.PERCENTILE.INC($H$7:$H$39,0.75),"High",IF(H9<=_xlfn.PERCENTILE.INC($H$7:$H$39,0.25),"Low","Medium")) -> Medium | J9: =IF(E9>=_xlfn.PERCENTILE.INC($E$7:$E$39,0.75),"High Size", IF(E9<=_xlfn.PERCENTILE.INC($E$7:$E$39,0.25),"Low Size","Medium Size")) -> High Size
C10: Uttar Pradesh | D10: 6946588.3 | E10: 13357207 | F10: 1.4267913e+08 | G10: =E10-D10 -> 6410618.7 | H10: =((E10-D10)/D10)*100 -> 92.284419 | I10: =IF(H10>=_xlfn.PERCENTILE.INC($H$7:$H$39,0.75),"High",IF(H10<=_xlfn.PERCENTILE.INC($H$7:$H$39,0.25),"Low","Medium")) -> Medium | J10: =IF(E10>=_xlfn.PERCENTILE.INC($E$7:$E$39,0.75),"High Size", IF(E10<=_xlfn.PERCENTILE.INC($E$7:$E$39,0.25),"Low Size","Medium Size")) -> High Size
C11: Karnataka | D11: 6044367 | E11: 12975636 | F11: 1.3429925e+08 | G11: =E11-D11 -> 6931268.6 | H11: =((E11-D11)/D11)*100 -> 114.67319 | I11: =IF(H11>=_xlfn.PERCENTILE.INC($H$7:$H$39,0.75),"High",IF(H11<=_xlfn.PERCENTILE.INC($H$7:$H$39,0.25),"Low","Medium")) -> Medium | J11: =IF(E11>=_xlfn.PERCENTILE.INC($E$7:$E$39,0.75),"High Size", IF(E11<=_xlfn.PERCENTILE.INC($E$7:$E$39,0.25),"Low Size","Medium Size")) -> High Size
C12: West Bengal | D12: 6795832 | E12: 12796876 | F12: 1.3850122e+08 | G12: =E12-D12 -> 6001044.5 | H12: =((E12-D12)/D12)*100 -> 88.30478 | I12: =IF(H12>=_xlfn.PERCENTILE.INC($H$7:$H$39,0.75),"High",IF(H12<=_xlfn.PERCENTILE.INC($H$7:$H$39,0.25),"Low","Medium")) -> Medium | J12: =IF(E12>=_xlfn.PERCENTILE.INC($E$7:$E$39,0.75),"High Size", IF(E12<=_xlfn.PERCENTILE.INC($E$7:$E$39,0.25),"Low Size","Medium Size")) -> High Size
C13: Telangana | D13: 3747813 | E13: 11532259 | F13: 1.0859181e+08 | G13: =E13-D13 -> 7784445.7 | H13: =((E13-D13)/D13)*100 -> 207.70635 | I13: =IF(H13>=_xlfn.PERCENTILE.INC($H$7:$H$39,0.75),"High",IF(H13<=_xlfn.PERCENTILE.INC($H$7:$H$39,0.25),"Low","Medium")) -> High | J13: =IF(E13>=_xlfn.PERCENTILE.INC($E$7:$E$39,0.75),"High Size", IF(E13<=_xlfn.PERCENTILE.INC($E$7:$E$39,0.25),"Low Size","Medium Size")) -> High Size
C14: Kerala | D14: 5321692 | E14: 10329246 | F14: 1.1085056e+08 | G14: =E14-D14 -> 5007554.3 | H14: =((E14-D14)/D14)*100 -> 94.097034 | I14: =IF(H14>=_xlfn.PERCENTILE.INC($H$7:$H$39,0.75),"High",IF(H14<=_xlfn.PERCENTILE.INC($H$7:$H$39,0.25),"Low","Medium")) -> Medium | J14: =IF(E14>=_xlfn.PERCENTILE.INC($E$7:$E$39,0.75),"High Size", IF(E14<=_xlfn.PERCENTILE.INC($E$7:$E$39,0.25),"Low Size","Medium Size")) -> High Size
C15: Rajasthan | D15: 4374625.4 | E15: 9626058.7 | F15: 95788158 | G15: =E15-D15 -> 5251433.2 | H15: =((E15-D15)/D15)*100 -> 120.04304 | I15: =IF(H15>=_xlfn.PERCENTILE.INC($H$7:$H$39,0.75),"High",IF(H15<=_xlfn.PERCENTILE.INC($H$7:$H$39,0.25),"Low","Medium")) -> Medium | J15: =IF(E15>=_xlfn.PERCENTILE.INC($E$7:$E$39,0.75),"High Size", IF(E15<=_xlfn.PERCENTILE.INC($E$7:$E$39,0.25),"Low Size","Medium Size")) -> High Size
C16: Haryana | D16: 3310741.6 | E16: 8077333.1 | F16: 82970707 | G16: =E16-D16 -> 4766591.5 | H16: =((E16-D16)/D16)*100 -> 143.97353 | I16: =IF(H16>=_xlfn.PERCENTILE.INC($H$7:$H$39,0.75),"High",IF(H16<=_xlfn.PERCENTILE.INC($H$7:$H$39,0.25),"Low","Medium")) -> Medium | J16: =IF(E16>=_xlfn.PERCENTILE.INC($E$7:$E$39,0.75),"High Size", IF(E16<=_xlfn.PERCENTILE.INC($E$7:$E$39,0.25),"Low Size","Medium Size")) -> Medium Size
C17: Delhi | D17: 4212068.3 | E17: 7967058.8 | F17: 89963209 | G17: =E17-D17 -> 3754990.5 | H17: =((E17-D17)/D17)*100 -> 89.148376 | I17: =IF(H17>=_xlfn.PERCENTILE.INC($H$7:$H$39,0.75),"High",IF(H17<=_xlfn.PERCENTILE.INC($H$7:$H$39,0.25),"Low","Medium")) -> Medium | J17: =IF(E17>=_xlfn.PERCENTILE.INC($E$7:$E$39,0.75),"High Size", IF(E17<=_xlfn.PERCENTILE.INC($E$7:$E$39,0.25),"Low Size","Medium Size")) -> Medium Size
C18: Madhya Pradesh | D18: 3378935 | E18: 6560080 | F18: 72576901 | G18: =E18-D18 -> 3181145 | H18: =((E18-D18)/D18)*100 -> 94.14638 | I18: =IF(H18>=_xlfn.PERCENTILE.INC($H$7:$H$39,0.75),"High",IF(H18<=_xlfn.PERCENTILE.INC($H$7:$H$39,0.25),"Low","Medium")) -> Medium | J18: =IF(E18>=_xlfn.PERCENTILE.INC($E$7:$E$39,0.75),"High Size", IF(E18<=_xlfn.PERCENTILE.INC($E$7:$E$39,0.25),"Low Size","Medium Size")) -> Medium Size
... C39: Arunachal Pradesh | D39: 59892 | E39: 63337.742 | F39: 863357.54 | G39: =E39-D39 -> 3445.7416 | H39: =((E39-D39)/D39)*100 -> 5.7532586 | I39: =IF(H39>=_xlfn.PERCENTILE.INC($H$7:$H$39,0.75),"High",IF(H39<=_xlfn.PERCENTILE.INC($H$7:$H$39,0.25),"Low","Medium")) -> Low | J39: =IF(E39>=_xlfn.PERCENTILE.INC($E$7:$E$39,0.75),"High Size", IF(E39<=_xlfn.PERCENTILE.INC($E$7:$E$39,0.25),"Low Size","Medium Size")) -> Low Size
C40: Grand Total | D40: 89319170 | E40: 1.8242096e+08 | F40: 1.9192866e+09 | G40: =E40-D40 -> 93101791 | H40: =((E40-D40)/D40)*100 -> 104.23495 | N40: State Analysis
N43: HIGH SIZE | O43: MEDIUM SIZE | P43: LOW SIZE
M44: HIGH GROWTH | N44: Gujarat, Telangana | O44: Uttarakhand, Jharkhand, Meghalaya | P44: Tripura, Mizoram, Sikkim, Andaman & Nicobar Islands
M45: MEDIUM GROWTH | N45: Tamil Nadu, Uttar Pradesh, Karnataka, West Bengal, Kerala, Rajasthan | O45: Haryana, Delhi, Madhya Pradesh, Andhra Pradesh, Odisha, Chattishgarh, Himachal Pradesh | P45: Goa, Manipur
M46: LOW GROWTH | N46: Maharashtra | O46: Bihar, Punjab, Assam, Chandigarh, Jammu & Kashmir | P46: Nagaland, Puducherry, Arunachal Pradesh
M52: High Growth + High Size → Star States
M54: High Growth + Low Size → Emerging States
M56: Low Growth + High Size → Mature / Saturated States
M58: Low Growth + Low Size → Lagging States
M61: DESCRIPIVE STATISTICS GSVA (2023-24)
M63: MEAN | N63: =AVERAGE(E7:E39) -> 5527907.9
M64: MEDIAN | N64: =MEDIAN(E7:E39) -> 3172405
M65: Std. Deviation | N65: =_xlfn.STDEV.S(E7:E39) -> 5635979.8
M66: MAXIMUM | N66: =MAX(E7:E39) -> 17628321
M67: Minimum | N67: =MIN(E7:E39) -> 63337.742
M68: Q1 | N68: =_xlfn.QUARTILE.INC(E7:E39,1) -> 554534
M69: Q3 | N69: =_xlfn.QUARTILE.INC(E7:E39,3) -> 9626058.7
M70: IQR | N70: =N69-N68 -> 9071524.7
M72: DESCRIPIVE STATISTICS GSVA Growth Column
M73: MEAN | N73: =AVERAGE(H7:H39) -> 124.26703
M74: MEDIAN | N74: =MEDIAN(H7:H39) -> 100.56049
M75: Std. Deviation | N75: =_xlfn.STDEV.S(H7:H39) -> 93.15084
M76: MAXIMUM | N76: =MAX(H7:H39) -> 458.41298
M77: Minimum | N77: =MIN(H7:H39) -> -0.042123782
...

Sheet UPI_Retail_Ratio
A1: Year | B1: UPI Value (in Cr.) | C1: National Retail GSVA (Rs. in lakh) | D1: UPI Share %
A2: 2011-12 | B2: 0 | C2: 89319170 | D2: 0
A3: 2012-13 | B3: 0 | C3: 97674458 | D3: 0
A4: 2013-14 | B4: 0 | C4: 1.0364521e+08 | D4: 0
A5: 2014-15 | B5: 0 | C5: 1.1007491e+08 | D5: 0
A6: 2015-16 | B6: 0 | C6: 1.1780437e+08 | D6: 0
A7: 2016-17 | B7: 6952.14 | C7: 1.2720199e+08 | D7: =B7/C7 -> 5.4654334e-05
A8: 2017-18 | B8: 109831.8 | C8: 1.401099e+08 | D8: =B8/C8 -> 0.00078389752
A9: 2018-19 | B9: 876970.72 | C9: 1.5582372e+08 | D9: =B9/C9 -> 0.0056279666
A10: 2019-20 | B10: 2131730.1 | C10: 1.6532543e+08 | D10: =B10/C10 -> 0.012894145
A11: 2020-21 | B11: 4103653.6 | C11: 1.3414564e+08 | D11: =B11/C11 -> 0.030591031
A12: 2021-22 | B12: 8417572.5 | C12: 1.4885649e+08 | D12: =B12/C12 -> 0.05654824
A13: 2022-23 | B13: 13920676 | C13: 1.7054221e+08 | D13: =B13/C13 -> 0.08162599
A14: 2023-24 | B14: 19995086 | C14: 1.8242096e+08 | D14: =B14/C14 -> 0.10960958

Sheet Retail_GSVA_STATES_PIVOT_TABLE
A3: Sum of Retail_GSVA (Rs. in lakh) | B3: Column Labels
A4: Row Labels | B4: 2011-12 | C4: 2012-13 | D4: 2013-14 | E4: 2014-15 | F4: 2015-16 | G4: 2016-17 | H4: 2017-18 | I4: 2018-19 | J4: 2019-20 | K4: 2020-21 | L4: 2021-22 | M4: 2022-23 | N4: 2023-24 | O4: 2024-25 | P4: Grand Total
A5: Andaman & Nicobar Islands | B5: 33936.692 | C5: 38829.343 | D5: 44996.267 | E5: 46386.012 | F5: 48380.359 | G5: 52295.763 | H5: 63072.556 | I5: 81279.805 | J5: 77062.155 | K5: 61438.844 | L5: 69459.284 | M5: 79929.3 | N5: 89929.312 | P5: 786995.69
A6: Andhra Pradesh | B6: 2673500 | C6: 2955400 | D6: 3314900 | E6: 3678886 | F6: 4321773 | G6: 4345007 | H6: 4728082.2 | I6: 5254769.9 | J6: 5577694.9 | K6: 4299583.2 | L6: 4909791.6 | M6: 5798289 | N6: 6405717.1 | O6: 6992062 | P6: 65255456
A7: Arunachal Pradesh | B7: 59892 | C7: 46755 | D7: 60541 | E7: 52921 | F7: 51686 | G7: 71123 | H7: 67127 | I7: 69813 | J7: 75961 | K7: 64551 | L7: 55145.416 | M7: 60404.121 | N7: 63337.742 | O7: 64100.258 | P7: 863357.54
A8: Assam | B8: 2045676 | C8: 2127460 | D8: 2262227 | E8: 2534132 | F8: 2223850 | G8: 2206094 | H8: 2372154 | I8: 2313574 | J8: 2410026 | K8: 3778776 | L8: 1839162 | M8: 2020860.6 | N8: 2203697.8 | O8: 2390247.2 | P8: 32727937
A9: Bihar | B9: 4390442.1 | C9: 4672877.2 | D9: 4568274.7 | E9: 4262584.9 | F9: 5042354.6 | G9: 5445576.7 | H9: 6092899.8 | I9: 6600717.7 | J9: 6875796.8 | K9: 5778900.3 | L9: 5602045.4 | M9: 6491113 | N9: 6535861.6 | O9: 6836466 | P9: 79195911
A10: Chandigarh | B10: 614134 | C10: 682914.52 | D10: 738834.57 | E10: 754141.6 | F10: 812027.46 | G10: 897599.53 | H10: 977879 | I10: 1053525 | J10: 1141776 | K10: 856789 | L10: 950529 | M10: 1078803 | N10: 1140548 | P10: 11699501
A11: Chhattisgarh | B11: 932617 | C11: 1021682 | D11: 1129497 | E11: 1154290 | F11: 1215208 | G11: 1538875 | H11: 1417566 | I11: 1558394 | J11: 1606573 | K11: 1218717 | L11: 1325511 | M11: 1643293 | N11: 1962075 | O11: 2237854 | P11: 19962152
A12: Delhi | B12: 4212068.3 | C12: 4589076.7 | D12: 5028155.7 | E12: 5120383 | F12: 5931557.7 | G12: 6245681.8 | H12: 6820833.6 | I12: 7520088.9 | J12: 7947769.7 | K12: 6143522.4 | L12: 6608201.2 | M12: 7330734.9 | N12: 7967058.8 | O12: 8498076.3 | P12: 89963209
A13: Goa | B13: 259614.66 | C13: 238037.68 | D13: 241585.24 | E13: 250266.04 | F13: 269968.81 | G13: 314038.86 | H13: 293828.19 | I13: 380558.18 | J13: 388523.9 | K13: 300523.81 | L13: 346133.58 | M13: 444105.61 | N13: 487812.49 | P13: 4214997
A14: Gujarat | B14: 6646396.1 | C14: 7862424.1 | D14: 8098296.8 | E14: 8932421.4 | F14: 9575555.7 | G14: 10648018 | H14: 11957724 | I14: 13344820 | J14: 14616582 | K14: 12832721 | L14: 13857576 | M14: 15315062 | N14: 17034179 | P14: 1.5072178e+08
A15: Haryana | B15: 3310741.6 | C15: 3623928.6 | D15: 3843440.5 | E15: 4309744.1 | F15: 5032464.8 | G15: 5598673.4 | H15: 6264536.1 | I15: 6927780 | J15: 7440278.5 | K15: 5948636.1 | L15: 6538523.2 | M15: 7288426.3 | N15: 8077333.1 | O15: 8766200.6 | P15: 82970707
A16: Himachal Pradesh | B16: 456828.62 | C16: 475494.53 | D16: 507916.09 | E16: 566701.57 | F16: 647428.17 | G16: 683934.72 | H16: 740544.64 | I16: 790768.11 | J16: 863668.08 | K16: 872056.2 | L16: 875257.1 | M16: 960671.56 | N16: 1087133.2 | O16: 1130040.6 | P16: 10658443
A17: Jammu & Kashmir | B17: 667074.2 | C17: 751709.4 | D17: 787767.02 | E17: 765735.16 | F17: 857054.2 | G17: 911073.1 | H17: 1012473.4 | I17: 1103135.5 | J17: 1102206.9 | K17: 781600.31 | L17: 941257.81 | M17: 1106154.2 | N17: 1114971.5 | O17: 1194096.5 | P17: 13096309
A18: Jharkhand | B18: 1152143 | C18: 1287305 | D18: 1400566 | E18: 1549332 | F18: 1777188 | G18: 2017464 | H18: 2275871 | I18: 2656896 | J18: 2928867 | K18: 2423282 | L18: 2567872 | M18: 3001476 | N18: 3113077 | O18: 3244628 | P18: 31395967
A19: Karnataka | B19: 6044367 | C19: 6441601.7 | D19: 7093957.8 | E19: 7560180.9 | F19: 7734152.5 | G19: 8557165.3 | H19: 9686849.9 | I19: 11058684 | J19: 11720487 | K19: 8758051.5 | L19: 10398482 | M19: 12533066 | N19: 12975636 | O19: 13736566 | P19: 1.3429925e+08
A20: Kerala | B20: 5321692 | C20: 6056645 | D20: 6191493 | E20: 6572440.8 | F20: 7068460.7 | G20: 7188898.8 | H20: 7738373 | I20: 8545827.5 | J20: 9117190.7 | K20: 6885193.8 | L20: 8349769.1 | M20: 9924364.7 | N20: 10329246 | O20: 11560960 | P20: 1.1085056e+08
A21: Madhya Pradesh | B21: 3378935 | C21: 3747267 | D21: 3890257 | E21: 4062768 | F21: 4287194 | G21: 4830781 | H21: 5282407 | I21: 6079542 | J21: 6301514 | K21: 4838760 | L21: 5695609 | M21: 6471506 | N21: 6560080 | O21: 7150281 | P21: 72576901
A22: Maharashtra | B22: 10560912 | C22: 11681539 | D22: 11513192 | E22: 11887258 | F22: 11940631 | G22: 13409917 | H22: 14504739 | I22: 16410748 | J22: 16931707 | K22: 12519903 | L22: 14665376 | M22: 16744694 | N22: 17628321 | O22: 18550729 | P22: 1.9894967e+08
A23: Manipur | B23: 156450 | C23: 130915 | D23: 190705 | E23: 203972 | F23: 237194 | G23: 256129 | H23: 283085 | I23: 307748 | J23: 327129 | K23: 253188 | L23: 282501 | M23: 315717 | N23: 337426 | P23: 3282159
A24: Meghalaya | B24: 258057.65 | C24: 298977.6 | D24: 328737.51 | E24: 336505.2 | F24: 394421.96 | G24: 446270.1 | H24: 498906.24 | I24: 572363.23 | J24: 628937.76 | K24: 525772.63 | L24: 540262.63 | M24: 607956.71 | N24: 663599.54 | O24: 712269.23 | P24: 6813038
A25: Mizoram | B25: 76482 | C25: 91962 | D25: 95240 | E25: 104821 | F25: 129144 | G25: 160617.31 | H25: 187624.82 | I25: 218659.81 | J25: 247947 | K25: 207396.14 | L25: 273800.71 | M25: 349486.71 | N25: 388938.08 | P25: 2532119.6
A26: Nagaland | B26: 105152.39 | C26: 113536.6 | D26: 108460.42 | E26: 110940.4 | F26: 127678.54 | G26: 126118.74 | H26: 161058.18 | I26: 182782.72 | J26: 201379.35 | K26: 186140.45 | L26: 140528.22 | M26: 166626.36 | N26: 178069.59 | P26: 1908472
A27: Odisha | B27: 2035854.4 | C27: 2274230.7 | D27: 2454254 | E27: 2652359.7 | F27: 3052006.1 | G27: 3165618.3 | H27: 3475493.9 | I27: 3757458 | J27: 4006859.5 | K27: 3048101.1 | L27: 3333851.5 | M27: 3772538.6 | N27: 4055158.4 | O27: 4622644.4 | P27: 45706429
A28: Puducherry | B28: 147477 | C28: 174572 | D28: 165482 | E28: 174562 | F28: 155361.69 | G28: 157358.1 | H28: 160976.93 | I28: 170228.06 | J28: 166241.07 | K28: 116410.66 | L28: 133252.27 | M28: 149812.37 | N28: 147414.88 | O28: 145485.59 | P28: 2164634.6
A29: Punjab | B29: 2532467 | C29: 2758214 | D29: 3004908 | E29: 3237423 | F29: 3458884 | G29: 3674850 | H29: 3934840 | I29: 4204671 | J29: 4466272 | K29: 3882005 | L29: 4222983 | M29: 4550015.7 | N29: 4754516.6 | O29: 5112608.4 | P29: 53794658
A30: Rajasthan | B30: 4374625.4 | C30: 4746078.7 | D30: 5082507.7 | E30: 5432676 | F30: 5697093.7 | G30: 5970325.9 | H30: 6703637.5 | I30: 7590102.6 | J30: 7875857.5 | K30: 6043360.7 | L30: 7371043.4 | M30: 8991630.5 | N30: 9626058.7 | O30: 10283160 | P30: 95788158
A31: Sikkim | B31: 31445.821 | C31: 50934.613 | D31: 60934.327 | E31: 60092.797 | F31: 61863.441 | G31: 66329.54 | H31: 76206.9 | I31: 87843.72 | J31: 98890.778 | K31: 106031.07 | L31: 118421.07 | M31: 152543.39 | N31: 175597.55 | P31: 1147135
A32: Tamil Nadu | B32: 7930218.9 | C32: 8910693.8 | D32: 9828600.7 | E32: 10228121 | F32: 10133545 | G32: 10811169 | H32: 11801744 | I32: 12964537 | J32: 13519999 | K32: 12780176 | L32: 13537069 | M32: 14896133 | N32: 15904886 | O32: 17328662 | P32: 1.7057555e+08
A33: Telangana | B33: 3747813 | C33: 4026649 | D33: 4357584 | E33: 5223022 | F33: 5854315 | G33: 6483197 | H33: 7514990 | I33: 8911381.3 | J33: 9731136 | K33: 7691857.8 | L33: 9386009 | M33: 10686573 | N33: 11532259 | O33: 13445026 | P33: 1.0859181e+08
A34: Tripura | B34: 226839 | C34: 262147 | D34: 250939 | E34: 318626 | F34: 241102 | G34: 279845 | H34: 384131 | I34: 452552 | J34: 525530 | K34: 404256 | L34: 424054 | M34: 540285 | N34: 554534 | O34: 614774.22 | P34: 5479614.2
A35: Uttar Pradesh | B35: 6946588.3 | C35: 6976021.1 | D35: 7679666.4 | E35: 8162572.3 | F35: 8944798.5 | G35: 9537001.3 | H35: 10242555 | I35: 10929187 | J35: 12036089 | K35: 9943130 | L35: 10843412 | M35: 12339047 | N35: 13357207 | O35: 14741853 | P35: 1.4267913e+08
A36: Uttarakhand | B36: 1192896 | C36: 1306187 | D36: 1418883 | E36: 1518569 | F36: 1691788 | G36: 1955352 | H36: 2222555 | I36: 2480838 | J36: 2646355 | K36: 1931675 | L36: 2388250 | M36: 2885557 | N36: 3172405 | O36: 3322050 | P36: 30133360
A37: West Bengal | B37: 6795832 | C37: 7252392 | D37: 7902411 | E37: 8250079 | F37: 8788238 | G37: 9149590 | H37: 10165132 | I37: 11242450 | J37: 11723125 | K37: 8663137 | L37: 10265349 | M37: 11845330 | N37: 12796876 | O37: 13661276 | P37: 1.3850122e+08
A38: Grand Total | B38: 89319170 | C38: 97674458 | D38: 1.0364521e+08 | E38: 1.1007491e+08 | F38: 1.1780437e+08 | G38: 1.2720199e+08 | H38: 1.401099e+08 | I38: 1.5582372e+08 | J38: 1.6532543e+08 | K38: 1.3414564e+08 | L38: 1.4885649e+08 | M38: 1.7054221e+08 | N38: 1.8242096e+08 | O38: 1.7634212e+08 | P38: 1.9192866e+09

Sheet Retail_GSVA_States
A1: S.No. | B1: State | C1: Year | D1: Retail_GSVA(Rs. in lakh)
A2: 1 | B2: Andhra Pradesh | C2: 2011-12 | D2: 2673500
A3: 2 | B3: Andhra Pradesh | C3: 2012-13 | D3: 2955400
A4: 3 | B4: Andhra Pradesh | C4: 2013-14 | D4: 3314900
A5: 4 | B5: Andhra Pradesh | C5: 2014-15 | D5: 3678886
A6: 5 | B6: Andhra Pradesh | C6: 2015-16 | D6: 4321773
A7: 6 | B7: Andhra Pradesh | C7: 2016-17 | D7: 4345007
A8: 7 | B8: Andhra Pradesh | C8: 2017-18 | D8: 4728082.2
A9: 8 | B9: Andhra Pradesh | C9: 2018-19 | D9: 5254769.9
A10: 9 | B10: Andhra Pradesh | C10: 2019-20 | D10: 5577694.9
A11: 10 | B11: Andhra Pradesh | C11: 2020-21 | D11: 4299583.2
A12: 11 | B12: Andhra Pradesh | C12: 2021-22 | D12: 4909791.6
A13: 12 | B13: Andhra Pradesh | C13: 2022-23 | D13: 5798289
... A455: 454 | B455: West Bengal | C455: 2024-25 | D455: 13661276

Sheet STATEWISE UPI DATA 2023-24
B2: 45017
A3: S.No. | B3: State / Union Territory | C3: Volume (in Mn ) | D3: Volume Contribution (%) | E3: Value (in Cr.) | F3: Value Contribution (%)
J5: STATEWISE UPI VALUE(in Cr.) Data 2023-24
A6: 1 | B6: MAHARASHTRA | C6: 1859.79 | D6: 0.2098 | E6: 260344.8 | F6: 0.1839
A7: 2 | B7: KARNATAKA | C7: 772.62 | D7: 0.0872 | E7: 114007.15 | F7: 0.0805 | I7: 45017 | J7: 45047 | K7: 45078 | L7: 45108 | M7: 45139 | N7: 45170 | O7: 45200 | P7: 45231 | Q7: 45261 | R7: 45292 | S7: 45323 | T7: 45352 | U7: TOTAL (2023-24)
A8: 3 | B8: TELANGANA | C8: 683.07 | D8: 0.0771 | E8: 121761.16 | F8: 0.086 | H8: STATE/UT
A9: 4 | B9: UTTAR PRADESH | C9: 569.78 | D9: 0.0643 | E9: 87585.09 | F9: 0.0619 | H9: MAHARASHTRA | I9: 260344.8 | J9: 258141.08 | K9: 274244.34 | L9: 278351.31 | M9: 282946.53 | N9: 286792.45 | O9: 297168.32 | P9: 289387.43 | Q9: 229753.56 | R9: 230102.34 | S9: 231170.06 | T9: 250484.52 | U9: =SUM(I9:T9) -> 3168886.7
A10: 5 | B10: TAMIL NADU | C10: 433.99 | D10: 0.049 | E10: 73484.77 | F10: 0.0519 | H10: KARNATAKA | I10: 114007.15 | J10: 118039.69 | K10: 116958.14 | L10: 122630.19 | M10: 126876.33 | N10: 125683.26 | O10: 133243.89 | P10: 132126.57 | Q10: 128746.92 | R10: 136780.78 | S10: 144752.39 | T10: 156929.06 | U10: =SUM(I10:T10) -> 1556774.4
A11: 6 | B11: RAJASTHAN | C11: 391.83 | D11: 0.0442 | E11: 64347.76 | F11: 0.0455 | H11: TELANGANA | I11: 121761.16 | J11: 129532.28 | K11: 129049.85 | L11: 127885.79 | M11: 127817.82 | N11: 121128.45 | O11: 132269.35 | P11: 118988.81 | Q11: 115581.23 | R11: 118540.28 | S11: 130330.17 | T11: 140637.92 | U11: =SUM(I11:T11) -> 1513523.1
A12: 7 | B12: MADHYA PRADESH | C12: 375.53 | D12: 0.0424 | E12: 56076.31 | F12: 0.0396 | H12: UTTAR PRADESH | I12: 87585.09 | J12: 94729.13 | K12: 90290.44 | L12: 90963.74 | M12: 94133.08 | N12: 95195.96 | O12: 107856.43 | P12: 131905.47 | Q12: 118318.89 | R12: 123049.67 | S12: 131906.83 | T12: 141964.06 | U12: =SUM(I12:T12) -> 1307898.8
A13: 8 | B13: DELHI | C13: 330.04 | D13: 0.0372 | E13: 46799.01 | F13: 0.0331 | H13: TAMIL NADU | I13: 73484.77 | J13: 78145.83 | K13: 79245.18 | L13: 83009.09 | M13: 84388.17 | N13: 85968.46 | O13: 81040.7 | P13: 87369.93 | Q13: 83498.19 | R13: 88612.57 | S13: 95903.84 | T13: 103876.55 | U13: =SUM(I13:T13) -> 1024543.3
A14: 9 | B14: GUJARAT | C14: 280.81 | D14: 0.0317 | E14: 46154.94 | F14: 0.0326 | H14: RAJASTHAN | I14: 64347.76 | J14: 59740.76 | K14: 63711.04 | L14: 66620.88 | M14: 67895.74 | N14: 69250.13 | O14: 87385.36 | P14: 72171.99 | Q14: 74773.6 | R14: 81026.02 | S14: 86997.16 | T14: 91202.44 | U14: =SUM(I14:T14) -> 885122.88
A15: 10 | B15: ANDHRA PRADESH | C15: 279.96 | D15: 0.0316 | E15: 59444.05 | F15: 0.042 | H15: MADHYA PRADESH | I15: 56076.31 | J15: 55560.85 | K15: 54882.65 | L15: 63069.1 | M15: 69380.56 | N15: 66104.53 | O15: 72771.58 | P15: 74471.53 | Q15: 84149.99 | R15: 90296.94 | S15: 68550.32 | T15: 76913.9 | U15: =SUM(I15:T15) -> 832228.26
A16: 11 | B16: BIHAR | C16: 267.97 | D16: 0.0302 | E16: 48787.79 | F16: 0.0345 | H16: DELHI | I16: 46799.01 | J16: 63055.85 | K16: 55593.65 | L16: 54276.07 | M16: 52953.64 | N16: 55139.92 | O16: 60577.68 | P16: 61568.09 | Q16: 53739.43 | R16: 62297.59 | S16: 88395.93 | T16: 97168.4 | U16: =SUM(I16:T16) -> 751565.26
A17: 12 | B17: WEST BENGAL | C17: 233.46 | D17: 0.0263 | E17: 43922.05 | F17: 0.031 | H17: GUJARAT | I17: 46154.94 | J17: 64986.38 | K17: 62976.99 | L17: 67084.86 | M17: 69909.85 | N17: 67178.11 | O17: 57809.55 | P17: 74054.42 | Q17: 49607.1 | R17: 53572.83 | S17: 57779.48 | T17: 59757.19 | U17: =SUM(I17:T17) -> 730871.7
A18: 13 | B18: HARYANA | C18: 225.35 | D18: 0.0254 | E18: 35256.24 | F18: 0.0249 | H18: ANDHRA PRADESH | I18: 59444.05 | J18: 47894.81 | K18: 46487.59 | L18: 49555.82 | M18: 51778.19 | N18: 51590.99 | O18: 71941.95 | P18: 60451.55 | Q18: 57762.41 | R18: 62424.28 | S18: 65518.15 | T18: 72235.02 | U18: =SUM(I18:T18) -> 697084.81
A19: 14 | B19: KERALA | C19: 201.13 | D19: 0.0227 | E19: 31243.16 | F19: 0.0221 | H19: BIHAR | I19: 48787.79 | J19: 51363.73 | K19: 49603.55 | L19: 50112.15 | M19: 47814.69 | N19: 48595.98 | O19: 54202.12 | P19: 58262.18 | Q19: 55538.69 | R19: 57546.14 | S19: 65150.33 | T19: 68656.44 | U19: =SUM(I19:T19) -> 655633.79
A20: 15 | B20: ODISHA | C20: 184.79 | D20: 0.0208 | E20: 28296.73 | F20: 0.02 | H20: WEST BENGAL | I20: 43922.05 | J20: 48233.44 | K20: 48095.78 | L20: 46720.09 | M20: 48819.44 | N20: 48707.55 | O20: 54677.68 | P20: 53753.8 | Q20: 53216.78 | R20: 57876.9 | S20: 61540.67 | T20: 66683.59 | U20: =SUM(I20:T20) -> 632247.77
... A42: 37 | B42: UNCLASSIFIED# | C42: 1162.65 | D42: 0.1312 | E42: 199181.5 | F42: 0.1407 | H42: ANDAMAN & NICOBAR | I42: 334.49 | J42: 412.84 | K42: 454.94 | L42: 318.73 | M42: 480.89 | N42: 481.1 | O42: 396.87 | P42: 427.62 | Q42: 491.18 | R42: 493.51 | S42: 488.59 | T42: 525.36 | U42: =SUM(I42:T42) -> 5306.12
H43: LADAKH | I43: 368.52 | J43: 336.3 | K43: 305.91 | L43: 475.02 | M43: 338.88 | N43: 347.87 | O43: 468.85 | P43: 369.58 | Q43: 368.7 | R43: 345.77 | S43: 339.04 | T43: 382.57 | U43: =SUM(I43:T43) -> 4447.01
H44: LAKSHADWEEP | I44: 23.34 | J44: 21.79 | K44: 20.5 | L44: 21.03 | M44: 23.1 | N44: 25.16 | O44: 30.13 | P44: 32.3 | Q44: 36.4 | R44: 41.42 | S44: 40.12 | T44: 44.73 | U44: =SUM(I44:T44) -> 360.02
H45: UNCLASSIFIED# | I45: 199181.5 | J45: 216957.59 | K45: 209034.13 | L45: 230885.29 | M45: 240823.86 | N45: 244896.29 | O45: 269012.53 | P45: 287627.38 | Q45: 475524.96 | R45: 426198.87 | S45: 339170.69 | T45: 368010.97 | U45: =SUM(I45:T45) -> 3507324.1
H46: TOTAL National | I46: =SUM(I9:I45) -> 1415504.7 | J46: =SUM(J9:J45) -> 1489145.5 | K46: =SUM(K9:K45) -> 1475464.3 | L46: =SUM(L9:L45) -> 1533536.4 | M46: =SUM(M9:M45) -> 1576536.6 | N46: =SUM(N9:N45) -> 1579133.2 | O46: =SUM(O9:O45) -> 1715768.4 | P46: =SUM(P9:P45) -> 1739740.6 | ... U46: =SUM(U9:U45) -> 19995086
T49: DESCRIPIVE STATISTICS UPI VALUE(2023-24) [Unclassified not included]
T50: MEAN | U50: =AVERAGE(U9:U44) -> 457993.38
B51: 45047 | T51: MEDIAN | U51: =MEDIAN(U9:U44) -> 182326.64
A52: S.No. | B52: State / Union Territory | C52: Volume (in Mn ) | D52: Volume Contribution (%) | E52: Value (in Cr.) | F52: Value Contribution (%) | T52: Std. Deviation | U52: =_xlfn.STDEV.S(U9:U44) -> 648364.55
T53: MAXIMUM | U53: =MAX(U9:U44) -> 3168886.7
A54: 1 | B54: MAHARASHTRA | C54: 1859.62 | D54: 0.1975 | E54: 258141.08 | F54: 0.1733 | T54: Minimum | U54: =MIN(U9:U44) -> 360.02
A55: 2 | B55: KARNATAKA | C55: 797.62 | D55: 0.0847 | E55: 118039.69 | F55: 0.0793 | T55: Q1 | U55: =_xlfn.QUARTILE.INC(U9:U44,1) -> 15809.538
A56: 3 | B56: TELANGANA | C56: 716.76 | D56: 0.0761 | E56: 129532.28 | F56: 0.087 | T56: Q3 | U56: =_xlfn.QUARTILE.INC(U9:U44,3) -> 705531.53
A57: 4 | B57: UTTAR PRADESH | C57: 612.76 | D57: 0.0651 | E57: 94729.13 | F57: 0.0636 | T57: IQR | U57: =U56-U55 -> 689721.99
A58: 5 | B58: TAMIL NADU | C58: 459.82 | D58: 0.0488 | E58: 78145.83 | F58: 0.0525
A59: 6 | B59: MADHYA PRADESH | C59: 397.53 | D59: 0.0422 | E59: 59740.76 | F59: 0.0401
A60: 7 | B60: DELHI | C60: 387.94 | D60: 0.0412 | E60: 55560.85 | F60: 0.0373
A61: 8 | B61: RAJASTHAN | C61: 382.58 | D61: 0.0406 | E61: 63055.85 | F61: 0.0423
A62: 9 | B62: ANDHRA PRADESH | C62: 300.2 | D62: 0.0319 | E62: 64986.38 | F62: 0.0436
A63: 10 | B63: GUJARAT | C63: 288.57 | D63: 0.0306 | E63: 47894.81 | F63: 0.0322
A64: 11 | B64: BIHAR | C64: 280.34 | D64: 0.0298 | E64: 51363.73 | F64: 0.0345
A65: 12 | B65: WEST BENGAL | C65: 263.52 | D65: 0.028 | E65: 48233.44 | F65: 0.0324
...

Sheet UPI_State_Snapshot_2023_24
A1: Sr. No. | B1: State / Union Territory | C1: UPI Value (2023-24) | D1: UPI Share % (state UPI value/Total National Value) | E1: Retail GSVA Growth Category | F1: Retail GSVA Size Category | G1: Classification Type
A2: 1 | B2: MAHARASHTRA | C2: 3168886.7 | D2: =(C2 / SUM($C$2:$C$34))*100 -> 19.236357 | E2: =_xlfn.XLOOKUP(UPI_State_Snapshot_2023_24!B2,'REATIL GSVA WORK'!$C$7:$C$39,'REATIL GSVA WORK'!$I$7:$I$39) -> Low | F2: =_xlfn.XLOOKUP(UPI_State_Snapshot_2023_24!B2,'REATIL GSVA WORK'!$C$7:$C$39,'REATIL GSVA WORK'!$J$7:$J$39) -> High Size | G2: =IF( AND(F2="High Size",E2="High",D2>=MEDIAN($D$2:$D$34)), "Core Growth Engine", IF( AND(E2="High",D2<MEDIAN($D$2:$D$34)), "Emerging Growth Market", IF( D2<MEDIAN($D$2:$D$34), "Low Adoption & Low Maturity", "Digitally Mature Market" ))) -> Digitally Mature Market
A3: 2 | B3: KARNATAKA | C3: 1556774.4 | D3: =(C3 / SUM($C$2:$C$37))*100 -> 9.4502169 | E3: =_xlfn.XLOOKUP(UPI_State_Snapshot_2023_24!B3,'REATIL GSVA WORK'!$C$7:$C$39,'REATIL GSVA WORK'!$I$7:$I$39) -> Medium | F3: =_xlfn.XLOOKUP(UPI_State_Snapshot_2023_24!B3,'REATIL GSVA WORK'!$C$7:$C$39,'REATIL GSVA WORK'!$J$7:$J$39) -> High Size | G3: =IF( AND(F3="High Size",E3="High",D3>=MEDIAN($D$2:$D$34)), "Core Growth Engine", IF( AND(E3="High",D3<MEDIAN($D$2:$D$34)), "Emerging Growth Market", IF( D3<MEDIAN($D$2:$D$34), "Low Adoption & Low Maturity", "Digitally Mature Market" ))) -> Digitally Mature Market
A4: 3 | B4: UTTAR PRADESH | C4: 1513523.1 | D4: =(C4 / SUM($C$2:$C$37))*100 -> 9.1876652 | E4: =_xlfn.XLOOKUP(UPI_State_Snapshot_2023_24!B4,'REATIL GSVA WORK'!$C$7:$C$39,'REATIL GSVA WORK'!$I$7:$I$39) -> Medium | F4: =_xlfn.XLOOKUP(UPI_State_Snapshot_2023_24!B4,'REATIL GSVA WORK'!$C$7:$C$39,'REATIL GSVA WORK'!$J$7:$J$39) -> High Size | G4: =IF( AND(F4="High Size",E4="High",D4>=MEDIAN($D$2:$D$34)), "Core Growth Engine", IF( AND(E4="High",D4<MEDIAN($D$2:$D$34)), "Emerging Growth Market", IF( D4<MEDIAN($D$2:$D$34), "Low Adoption & Low Maturity", "Digitally Mature Market" ))) -> Digitally Mature Market
A5: 4 | B5: TELANGANA | C5: 1307898.8 | D5: =(C5 / SUM($C$2:$C$37))*100 -> 7.9394468 | E5: =_xlfn.XLOOKUP(UPI_State_Snapshot_2023_24!B5,'REATIL GSVA WORK'!$C$7:$C$39,'REATIL GSVA WORK'!$I$7:$I$39) -> High | F5: =_xlfn.XLOOKUP(UPI_State_Snapshot_2023_24!B5,'REATIL GSVA WORK'!$C$7:$C$39,'REATIL GSVA WORK'!$J$7:$J$39) -> High Size | G5: =IF( AND(F5="High Size",E5="High",D5>=MEDIAN($D$2:$D$34)), "Core Growth Engine", IF( AND(E5="High",D5<MEDIAN($D$2:$D$34)), "Emerging Growth Market", IF( D5<MEDIAN($D$2:$D$34), "Low Adoption & Low Maturity", "Digitally Mature Market" ))) -> Core Growth Engine
A6: 5 | B6: TAMIL NADU | C6: 1024543.3 | D6: =(C6 / SUM($C$2:$C$37))*100 -> 6.2193703 | E6: =_xlfn.XLOOKUP(UPI_State_Snapshot_2023_24!B6,'REATIL GSVA WORK'!$C$7:$C$39,'REATIL GSVA WORK'!$I$7:$I$39) -> Medium | F6: =_xlfn.XLOOKUP(UPI_State_Snapshot_2023_24!B6,'REATIL GSVA WORK'!$C$7:$C$39,'REATIL GSVA WORK'!$J$7:$J$39) -> High Size | G6: =IF( AND(F6="High Size",E6="High",D6>=MEDIAN($D$2:$D$34)), "Core Growth Engine", IF( AND(E6="High",D6<MEDIAN($D$2:$D$34)), "Emerging Growth Market", IF( D6<MEDIAN($D$2:$D$34), "Low Adoption & Low Maturity", "Digitally Mature Market" ))) -> Digitally Mature Market
A7: 6 | B7: RAJASTHAN | C7: 885122.88 | D7: =(C7 / SUM($C$2:$C$37))*100 -> 5.373035 | E7: =_xlfn.XLOOKUP(UPI_State_Snapshot_2023_24!B7,'REATIL GSVA WORK'!$C$7:$C$39,'REATIL GSVA WORK'!$I$7:$I$39) -> Medium | F7: =_xlfn.XLOOKUP(UPI_State_Snapshot_2023_24!B7,'REATIL GSVA WORK'!$C$7:$C$39,'REATIL GSVA WORK'!$J$7:$J$39) -> High Size | G7: =IF( AND(F7="High Size",E7="High",D7>=MEDIAN($D$2:$D$34)), "Core Growth Engine", IF( AND(E7="High",D7<MEDIAN($D$2:$D$34)), "Emerging Growth Market", IF( D7<MEDIAN($D$2:$D$34), "Low Adoption & Low Maturity", "Digitally Mature Market" ))) -> Digitally Mature Market
A8: 7 | B8: MADHYA PRADESH | C8: 832228.26 | D8: =(C8 / SUM($C$2:$C$37))*100 -> 5.0519444 | E8: =_xlfn.XLOOKUP(UPI_State_Snapshot_2023_24!B8,'REATIL GSVA WORK'!$C$7:$C$39,'REATIL GSVA WORK'!$I$7:$I$39) -> Medium | F8: =_xlfn.XLOOKUP(UPI_State_Snapshot_2023_24!B8,'REATIL GSVA WORK'!$C$7:$C$39,'REATIL GSVA WORK'!$J$7:$J$39) -> Medium Size | G8: =IF( AND(F8="High Size",E8="High",D8>=MEDIAN($D$2:$D$34)), "Core Growth Engine", IF( AND(E8="High",D8<MEDIAN($D$2:$D$34)), "Emerging Growth Market", IF( D8<MEDIAN($D$2:$D$34), "Low Adoption & Low Maturity", "Digitally Mature Market" ))) -> Digitally Mature Market
A9: 8 | B9: ANDHRA PRADESH | C9: 751565.26 | D9: =(C9 / SUM($C$2:$C$37))*100 -> 4.5622891 | E9: =_xlfn.XLOOKUP(UPI_State_Snapshot_2023_24!B9,'REATIL GSVA WORK'!$C$7:$C$39,'REATIL GSVA WORK'!$I$7:$I$39) -> Medium | F9: =_xlfn.XLOOKUP(UPI_State_Snapshot_2023_24!B9,'REATIL GSVA WORK'!$C$7:$C$39,'REATIL GSVA WORK'!$J$7:$J$39) -> Medium Size | G9: =IF( AND(F9="High Size",E9="High",D9>=MEDIAN($D$2:$D$34)), "Core Growth Engine", IF( AND(E9="High",D9<MEDIAN($D$2:$D$34)), "Emerging Growth Market", IF( D9<MEDIAN($D$2:$D$34), "Low Adoption & Low Maturity", "Digitally Mature Market" ))) -> Digitally Mature Market
A10: 9 | B10: DELHI | C10: 730871.7 | D10: =(C10 / SUM($C$2:$C$37))*100 -> 4.4366713 | E10: =_xlfn.XLOOKUP(UPI_State_Snapshot_2023_24!B10,'REATIL GSVA WORK'!$C$7:$C$39,'REATIL GSVA WORK'!$I$7:$I$39) -> Medium | F10: =_xlfn.XLOOKUP(UPI_State_Snapshot_2023_24!B10,'REATIL GSVA WORK'!$C$7:$C$39,'REATIL GSVA WORK'!$J$7:$J$39) -> Medium Size | G10: =IF( AND(F10="High Size",E10="High",D10>=MEDIAN($D$2:$D$34)), "Core Growth Engine", IF( AND(E10="High",D10<MEDIAN($D$2:$D$34)), "Emerging Growth Market", IF( D10<MEDIAN($D$2:$D$34), "Low Adoption & Low Maturity", "Digitally Mature Market" ))) -> Digitally Mature Market
A11: 10 | B11: BIHAR | C11: 697084.81 | D11: =(C11 / SUM($C$2:$C$37))*100 -> 4.2315719 | E11: =_xlfn.XLOOKUP(UPI_State_Snapshot_2023_24!B11,'REATIL GSVA WORK'!$C$7:$C$39,'REATIL GSVA WORK'!$I$7:$I$39) -> Low | F11: =_xlfn.XLOOKUP(UPI_State_Snapshot_2023_24!B11,'REATIL GSVA WORK'!$C$7:$C$39,'REATIL GSVA WORK'!$J$7:$J$39) -> Medium Size | G11: =IF( AND(F11="High Size",E11="High",D11>=MEDIAN($D$2:$D$34)), "Core Growth Engine", IF( AND(E11="High",D11<MEDIAN($D$2:$D$34)), "Emerging Growth Market", IF( D11<MEDIAN($D$2:$D$34), "Low Adoption & Low Maturity", "Digitally Mature Market" ))) -> Digitally Mature Market
A12: 11 | B12: GUJARAT | C12: 655633.79 | D12: =(C12 / SUM($C$2:$C$37))*100 -> 3.9799483 | E12: =_xlfn.XLOOKUP(UPI_State_Snapshot_2023_24!B12,'REATIL GSVA WORK'!$C$7:$C$39,'REATIL GSVA WORK'!$I$7:$I$39) -> High | F12: =_xlfn.XLOOKUP(UPI_State_Snapshot_2023_24!B12,'REATIL GSVA WORK'!$C$7:$C$39,'REATIL GSVA WORK'!$J$7:$J$39) -> High Size | G12: =IF( AND(F12="High Size",E12="High",D12>=MEDIAN($D$2:$D$34)), "Core Growth Engine", IF( AND(E12="High",D12<MEDIAN($D$2:$D$34)), "Emerging Growth Market", IF( D12<MEDIAN($D$2:$D$34), "Low Adoption & Low Maturity", "Digitally Mature Market" ))) -> Core Growth Engine
A13: 12 | B13: WEST BENGAL | C13: 632247.77 | D13: =(C13 / SUM($C$2:$C$37))*100 -> 3.8379862 | E13: =_xlfn.XLOOKUP(UPI_State_Snapshot_2023_24!B13,'REATIL GSVA WORK'!$C$7:$C$39,'REATIL GSVA WORK'!$I$7:$I$39) -> Medium | F13: =_xlfn.XLOOKUP(UPI_State_Snapshot_2023_24!B13,'REATIL GSVA WORK'!$C$7:$C$39,'REATIL GSVA WORK'!$J$7:$J$39) -> High Size | G13: =IF( AND(F13="High Size",E13="High",D13>=MEDIAN($D$2:$D$34)), "Core Growth Engine", IF( AND(E13="High",D13<MEDIAN($D$2:$D$34)), "Emerging Growth Market", IF( D13<MEDIAN($D$2:$D$34), "Low Adoption & Low Maturity", "Digitally Mature Market" ))) -> Digitally Mature Market
A14: 13 | B14: HARYANA | C14: 502322.19 | D14: =(C14 / SUM($C$2:$C$37))*100 -> 3.0492882 | E14: =_xlfn.XLOOKUP(UPI_State_Snapshot_2023_24!B14,'REATIL GSVA WORK'!$C$7:$C$39,'REATIL GSVA WORK'!$I$7:$I$39) -> Medium | F14: =_xlfn.XLOOKUP(UPI_State_Snapshot_2023_24!B14,'REATIL GSVA WORK'!$C$7:$C$39,'REATIL GSVA WORK'!$J$7:$J$39) -> Medium Size | G14: =IF( AND(F14="High Size",E14="High",D14>=MEDIAN($D$2:$D$34)), "Core Growth Engine", IF( AND(E14="High",D14<MEDIAN($D$2:$D$34)), "Emerging Growth Market", IF( D14<MEDIAN($D$2:$D$34), "Low Adoption & Low Maturity", "Digitally Mature Market" ))) -> Digitally Mature Market
... A34: 33 | B34: ANDAMAN & NICOBAR | C34: 5306.12 | D34: =(C34 / SUM($C$2:$C$37))*100 -> 0.032210182 | E34: =_xlfn.XLOOKUP(UPI_State_Snapshot_2023_24!B34,'REATIL GSVA WORK'!$C$7:$C$39,'REATIL GSVA WORK'!$I$7:$I$39) -> High | F34: =_xlfn.XLOOKUP(UPI_State_Snapshot_2023_24!B34,'REATIL GSVA WORK'!$C$7:$C$39,'REATIL GSVA WORK'!$J$7:$J$39) -> Low Size | G34: =IF( AND(F34="High Size",E34="High",D34>=MEDIAN($D$2:$D$34)), "Core Growth Engine", IF( AND(E34="High",D34<MEDIAN($D$2:$D$34)), "Emerging Growth Market", IF( D34<MEDIAN($D$2:$D$34), "Low Adoption & Low Maturity", "Digitally Mature Market" ))) -> Emerging Growth Market
B39: Ladakh, Lakshadweep, Dadra & Nagar Haveli & Daman & Diu data were excluded from the state-wise analysis to ensure data comparability.
B41: Classification | C41: Meaning
B42: Core Growth Engine | C42: Large, fast-growing, digitally strong
B43: Emerging Growth Market | C43: Growing fast but digitally weaker
B44: Low Adoption & Low Maturity | C44: Structural + digital lag
B45: Digitally Mature Market | C45: Strong digital usage, stable growth
